2024-01-26 17:42:48,988 - django.utils.autoreload - INFO - /app/polls/scrapers.py changed, reloading.
2024-01-26 19:01:39,168 - django.utils.autoreload - INFO - /app/django_celery_example/settings.py changed, reloading.
2024-01-26 19:12:42,768 - django.utils.autoreload - INFO - /app/django_celery_example/celery.py changed, reloading.
2024-01-26 19:13:06,722 - django.utils.autoreload - INFO - /app/django_celery_example/celery.py changed, reloading.
2024-01-26 19:13:37,973 - django.utils.autoreload - INFO - /app/django_celery_example/celery.py changed, reloading.
2024-01-26 19:14:48,182 - django.utils.autoreload - INFO - /app/django_celery_example/celery.py changed, reloading.
2024-01-26 19:16:09,857 - django.utils.autoreload - INFO - /app/django_celery_example/celery.py changed, reloading.
2024-01-26 19:34:22,897 - django.utils.autoreload - INFO - /app/django_celery_example/celery.py changed, reloading.
2024-01-26 19:34:26,905 - django.utils.autoreload - INFO - Watching for file changes with StatReloader
2024-01-26 19:40:48,801 - django.utils.autoreload - INFO - /app/django_celery_example/celery.py changed, reloading.
2024-01-26 19:40:49,873 - django.utils.autoreload - INFO - Watching for file changes with StatReloader
2024-01-26 19:41:11,517 - django.utils.autoreload - INFO - Watching for file changes with StatReloader
2024-01-26 19:41:15,237 - flower.command - INFO - Visit me at http://0.0.0.0:5555
2024-01-26 19:41:15,244 - flower.command - INFO - Broker: redis://redis:6379/0
2024-01-26 19:41:15,248 - flower.command - INFO - Registered tasks: 
['celery.accumulate',
 'celery.backend_cleanup',
 'celery.chain',
 'celery.chord',
 'celery.chord_unlock',
 'celery.chunks',
 'celery.group',
 'celery.map',
 'celery.starmap',
 'django_celery_example.celery.divide',
 'django_celery_example.celery.run_scraper_with_all_params']
2024-01-26 19:41:15,256 - kombu.mixins - INFO - Connected to redis://redis:6379/0
2024-01-26 19:47:59,374 - django.utils.autoreload - INFO - /app/polls/scrapers.py changed, reloading.
2024-01-26 19:48:01,693 - django.utils.autoreload - INFO - Watching for file changes with StatReloader
2024-01-26 19:48:26,861 - django.utils.autoreload - INFO - Watching for file changes with StatReloader
2024-01-26 19:48:29,723 - flower.command - INFO - Visit me at http://0.0.0.0:5555
2024-01-26 19:48:29,729 - flower.command - INFO - Broker: redis://redis:6379/0
2024-01-26 19:48:29,734 - flower.command - INFO - Registered tasks: 
['celery.accumulate',
 'celery.backend_cleanup',
 'celery.chain',
 'celery.chord',
 'celery.chord_unlock',
 'celery.chunks',
 'celery.group',
 'celery.map',
 'celery.starmap',
 'django_celery_example.celery.divide',
 'django_celery_example.celery.run_scraper_with_all_params']
2024-01-26 19:48:29,739 - kombu.mixins - INFO - Connected to redis://redis:6379/0
2024-01-26 19:49:50,385 - django.security.DisallowedHost - ERROR - Invalid HTTP_HOST header: '0.0.0.0:8010'. You may need to add '0.0.0.0' to ALLOWED_HOSTS.
Traceback (most recent call last):
  File "/usr/local/lib/python3.11/dist-packages/django/core/handlers/exception.py", line 55, in inner
    response = get_response(request)
               ^^^^^^^^^^^^^^^^^^^^^
  File "/usr/local/lib/python3.11/dist-packages/django/utils/deprecation.py", line 133, in __call__
    response = self.process_request(request)
               ^^^^^^^^^^^^^^^^^^^^^^^^^^^^^
  File "/usr/local/lib/python3.11/dist-packages/django/middleware/common.py", line 48, in process_request
    host = request.get_host()
           ^^^^^^^^^^^^^^^^^^
  File "/usr/local/lib/python3.11/dist-packages/django/http/request.py", line 150, in get_host
    raise DisallowedHost(msg)
django.core.exceptions.DisallowedHost: Invalid HTTP_HOST header: '0.0.0.0:8010'. You may need to add '0.0.0.0' to ALLOWED_HOSTS.
2024-01-26 19:49:50,435 - django.request - WARNING - Bad Request: /admin
2024-01-26 19:49:50,563 - django.security.DisallowedHost - ERROR - Invalid HTTP_HOST header: '0.0.0.0:8010'. You may need to add '0.0.0.0' to ALLOWED_HOSTS.
Traceback (most recent call last):
  File "/usr/local/lib/python3.11/dist-packages/django/core/handlers/exception.py", line 55, in inner
    response = get_response(request)
               ^^^^^^^^^^^^^^^^^^^^^
  File "/usr/local/lib/python3.11/dist-packages/django/utils/deprecation.py", line 133, in __call__
    response = self.process_request(request)
               ^^^^^^^^^^^^^^^^^^^^^^^^^^^^^
  File "/usr/local/lib/python3.11/dist-packages/django/middleware/common.py", line 48, in process_request
    host = request.get_host()
           ^^^^^^^^^^^^^^^^^^
  File "/usr/local/lib/python3.11/dist-packages/django/http/request.py", line 150, in get_host
    raise DisallowedHost(msg)
django.core.exceptions.DisallowedHost: Invalid HTTP_HOST header: '0.0.0.0:8010'. You may need to add '0.0.0.0' to ALLOWED_HOSTS.
2024-01-26 19:49:50,607 - django.request - WARNING - Bad Request: /favicon.ico
2024-01-26 19:50:01,042 - django.security.DisallowedHost - ERROR - Invalid HTTP_HOST header: '0.0.0.0:8010'. You may need to add '0.0.0.0' to ALLOWED_HOSTS.
Traceback (most recent call last):
  File "/usr/local/lib/python3.11/dist-packages/django/core/handlers/exception.py", line 55, in inner
    response = get_response(request)
               ^^^^^^^^^^^^^^^^^^^^^
  File "/usr/local/lib/python3.11/dist-packages/django/utils/deprecation.py", line 133, in __call__
    response = self.process_request(request)
               ^^^^^^^^^^^^^^^^^^^^^^^^^^^^^
  File "/usr/local/lib/python3.11/dist-packages/django/middleware/common.py", line 48, in process_request
    host = request.get_host()
           ^^^^^^^^^^^^^^^^^^
  File "/usr/local/lib/python3.11/dist-packages/django/http/request.py", line 150, in get_host
    raise DisallowedHost(msg)
django.core.exceptions.DisallowedHost: Invalid HTTP_HOST header: '0.0.0.0:8010'. You may need to add '0.0.0.0' to ALLOWED_HOSTS.
2024-01-26 19:50:01,080 - django.request - WARNING - Bad Request: /admin
2024-01-26 19:50:12,540 - django.request - WARNING - Not Found: /favicon.ico
2024-01-26 19:53:44,586 - django.request - WARNING - Not Found: /favicon.ico
2024-01-26 20:02:50,646 - django.utils.autoreload - INFO - /app/polls/views.py changed, reloading.
2024-01-26 20:02:52,545 - django.utils.autoreload - INFO - Watching for file changes with StatReloader
2024-01-26 20:05:19,002 - django.utils.autoreload - INFO - /app/polls/views.py changed, reloading.
2024-01-26 20:05:20,447 - django.utils.autoreload - INFO - Watching for file changes with StatReloader
2024-01-26 20:06:48,161 - django.utils.autoreload - INFO - /app/polls/views.py changed, reloading.
2024-01-26 20:06:49,610 - django.utils.autoreload - INFO - Watching for file changes with StatReloader
2024-01-26 20:07:43,566 - django.utils.autoreload - INFO - Watching for file changes with StatReloader
2024-01-26 20:07:47,034 - flower.command - INFO - Visit me at http://0.0.0.0:5555
2024-01-26 20:07:47,050 - flower.command - INFO - Broker: redis://redis:6379/0
2024-01-26 20:07:47,064 - flower.command - INFO - Registered tasks: 
['celery.accumulate',
 'celery.backend_cleanup',
 'celery.chain',
 'celery.chord',
 'celery.chord_unlock',
 'celery.chunks',
 'celery.group',
 'celery.map',
 'celery.starmap',
 'django_celery_example.celery.divide',
 'django_celery_example.celery.run_scraper_with_all_params_task']
2024-01-26 20:07:47,097 - kombu.mixins - INFO - Connected to redis://redis:6379/0
2024-01-26 20:09:08,543 - django.request - ERROR - Internal Server Error: /trigger_web_scraping_dou_api/
Traceback (most recent call last):
  File "/usr/local/lib/python3.11/dist-packages/django/core/handlers/exception.py", line 55, in inner
    response = get_response(request)
               ^^^^^^^^^^^^^^^^^^^^^
  File "/usr/local/lib/python3.11/dist-packages/django/core/handlers/base.py", line 197, in _get_response
    response = wrapped_callback(request, *callback_args, **callback_kwargs)
               ^^^^^^^^^^^^^^^^^^^^^^^^^^^^^^^^^^^^^^^^^^^^^^^^^^^^^^^^^^^^
  File "/usr/local/lib/python3.11/dist-packages/django/views/decorators/csrf.py", line 56, in wrapper_view
    return view_func(*args, **kwargs)
           ^^^^^^^^^^^^^^^^^^^^^^^^^^
  File "/usr/local/lib/python3.11/dist-packages/django/views/generic/base.py", line 104, in view
    return self.dispatch(request, *args, **kwargs)
           ^^^^^^^^^^^^^^^^^^^^^^^^^^^^^^^^^^^^^^^
  File "/usr/local/lib/python3.11/dist-packages/rest_framework/views.py", line 511, in dispatch
    self.response = self.finalize_response(request, response, *args, **kwargs)
                    ^^^^^^^^^^^^^^^^^^^^^^^^^^^^^^^^^^^^^^^^^^^^^^^^^^^^^^^^^^
  File "/usr/local/lib/python3.11/dist-packages/rest_framework/views.py", line 423, in finalize_response
    assert isinstance(response, HttpResponseBase), (
AssertionError: Expected a `Response`, `HttpResponse` or `HttpStreamingResponse` to be returned from the view, but received a `<class 'NoneType'>`
2024-01-26 20:09:08,781 - django.request - WARNING - Not Found: /favicon.ico
2024-01-26 20:10:11,439 - django.utils.autoreload - INFO - /app/polls/views.py changed, reloading.
2024-01-26 20:10:13,146 - django.utils.autoreload - INFO - Watching for file changes with StatReloader
2024-01-26 20:10:20,451 - django.request - WARNING - Not Found: /favicon.ico
2024-01-26 20:11:08,276 - django.utils.autoreload - INFO - /app/polls/views.py changed, reloading.
2024-01-26 20:11:10,086 - django.utils.autoreload - INFO - Watching for file changes with StatReloader
2024-01-26 20:13:30,780 - django.utils.autoreload - INFO - /app/polls/views.py changed, reloading.
2024-01-26 20:13:32,705 - django.utils.autoreload - INFO - Watching for file changes with StatReloader
2024-01-26 20:13:38,359 - django.utils.autoreload - INFO - /app/polls/views.py changed, reloading.
2024-01-26 20:13:39,624 - django.utils.autoreload - INFO - Watching for file changes with StatReloader
2024-01-26 20:13:43,952 - django.request - WARNING - Not Found: /favicon.ico
2024-01-26 20:18:11,093 - django.utils.autoreload - INFO - /app/polls/views.py changed, reloading.
2024-01-26 20:18:14,139 - django.utils.autoreload - INFO - Watching for file changes with StatReloader
2024-01-26 20:18:18,651 - django.utils.autoreload - INFO - /app/polls/views.py changed, reloading.
2024-01-26 20:18:19,662 - django.utils.autoreload - INFO - Watching for file changes with StatReloader
2024-01-26 20:18:44,609 - django.utils.autoreload - INFO - Watching for file changes with StatReloader
2024-01-26 20:18:47,596 - flower.command - INFO - Visit me at http://0.0.0.0:5555
2024-01-26 20:18:47,606 - flower.command - INFO - Broker: redis://redis:6379/0
2024-01-26 20:18:47,612 - flower.command - INFO - Registered tasks: 
['celery.accumulate',
 'celery.backend_cleanup',
 'celery.chain',
 'celery.chord',
 'celery.chord_unlock',
 'celery.chunks',
 'celery.group',
 'celery.map',
 'celery.starmap',
 'django_celery_example.celery.divide',
 'django_celery_example.celery.run_scraper_with_all_params_task']
2024-01-26 20:18:47,620 - kombu.mixins - INFO - Connected to redis://redis:6379/0
2024-01-26 20:20:26,169 - django.request - WARNING - Not Found: /favicon.ico
2024-01-26 20:21:22,676 - django.request - WARNING - Not Found: /favicon.ico
2024-01-26 20:40:37,487 - django.utils.autoreload - INFO - /app/polls/views.py changed, reloading.
2024-01-26 20:40:41,333 - django.utils.autoreload - INFO - Watching for file changes with StatReloader
2024-01-26 20:42:00,712 - django.utils.autoreload - INFO - /app/polls/views.py changed, reloading.
2024-01-26 20:42:01,758 - django.utils.autoreload - INFO - Watching for file changes with StatReloader
2024-01-26 20:42:43,419 - django.utils.autoreload - INFO - /app/polls/views.py changed, reloading.
2024-01-26 20:42:44,467 - django.utils.autoreload - INFO - Watching for file changes with StatReloader
2024-01-26 20:53:22,486 - celery.utils.dispatch.signal - ERROR - Signal handler <bound method DjangoFixup.on_import_modules of <celery.fixups.django.DjangoFixup object at 0x7ff18ec884d0>> raised: ModuleNotFoundError("No module named 'trigger_web_scraping_dou_api'")
Traceback (most recent call last):
  File "/usr/local/lib/python3.11/dist-packages/celery/utils/dispatch/signal.py", line 276, in send
    response = receiver(signal=self, sender=sender, **named)
               ^^^^^^^^^^^^^^^^^^^^^^^^^^^^^^^^^^^^^^^^^^^^^
  File "/usr/local/lib/python3.11/dist-packages/celery/fixups/django.py", line 97, in on_import_modules
    self.worker_fixup.validate_models()
  File "/usr/local/lib/python3.11/dist-packages/celery/fixups/django.py", line 137, in validate_models
    run_checks()
  File "/usr/local/lib/python3.11/dist-packages/django/core/checks/registry.py", line 88, in run_checks
    new_errors = check(app_configs=app_configs, databases=databases)
                 ^^^^^^^^^^^^^^^^^^^^^^^^^^^^^^^^^^^^^^^^^^^^^^^^^^^
  File "/usr/local/lib/python3.11/dist-packages/django/core/checks/urls.py", line 42, in check_url_namespaces_unique
    all_namespaces = _load_all_namespaces(resolver)
                     ^^^^^^^^^^^^^^^^^^^^^^^^^^^^^^
  File "/usr/local/lib/python3.11/dist-packages/django/core/checks/urls.py", line 61, in _load_all_namespaces
    url_patterns = getattr(resolver, "url_patterns", [])
                   ^^^^^^^^^^^^^^^^^^^^^^^^^^^^^^^^^^^^^
  File "/usr/local/lib/python3.11/dist-packages/django/utils/functional.py", line 57, in __get__
    res = instance.__dict__[self.name] = self.func(instance)
                                         ^^^^^^^^^^^^^^^^^^^
  File "/usr/local/lib/python3.11/dist-packages/django/urls/resolvers.py", line 715, in url_patterns
    patterns = getattr(self.urlconf_module, "urlpatterns", self.urlconf_module)
                       ^^^^^^^^^^^^^^^^^^^
  File "/usr/local/lib/python3.11/dist-packages/django/utils/functional.py", line 57, in __get__
    res = instance.__dict__[self.name] = self.func(instance)
                                         ^^^^^^^^^^^^^^^^^^^
  File "/usr/local/lib/python3.11/dist-packages/django/urls/resolvers.py", line 708, in urlconf_module
    return import_module(self.urlconf_name)
           ^^^^^^^^^^^^^^^^^^^^^^^^^^^^^^^^
  File "/usr/lib/python3.11/importlib/__init__.py", line 126, in import_module
    return _bootstrap._gcd_import(name[level:], package, level)
           ^^^^^^^^^^^^^^^^^^^^^^^^^^^^^^^^^^^^^^^^^^^^^^^^^^^^
  File "<frozen importlib._bootstrap>", line 1206, in _gcd_import
  File "<frozen importlib._bootstrap>", line 1178, in _find_and_load
  File "<frozen importlib._bootstrap>", line 1149, in _find_and_load_unlocked
  File "<frozen importlib._bootstrap>", line 690, in _load_unlocked
  File "<frozen importlib._bootstrap_external>", line 940, in exec_module
  File "<frozen importlib._bootstrap>", line 241, in _call_with_frames_removed
  File "/app/django_celery_example/urls.py", line 23, in <module>
    from polls.views import JournalJsonArrayOfDOUViewSet, DetailSingleJournalOfDOUViewSet
  File "/app/polls/views.py", line 16, in <module>
    from .services import JournalJsonArrayOfDOUService, DetailSingleJournalOfDOUService
  File "/app/polls/services.py", line 2, in <module>
    from trigger_web_scraping_dou_api.models import JournalJsonArrayOfDOU, DetailSingleJournalOfDOU
ModuleNotFoundError: No module named 'trigger_web_scraping_dou_api'
2024-01-26 20:53:22,516 - celery.utils.dispatch.signal - ERROR - Signal handler <bound method DjangoFixup.on_import_modules of <celery.fixups.django.DjangoFixup object at 0x7f9fdfbe0610>> raised: ModuleNotFoundError("No module named 'trigger_web_scraping_dou_api'")
Traceback (most recent call last):
  File "/usr/local/lib/python3.11/dist-packages/celery/utils/dispatch/signal.py", line 276, in send
    response = receiver(signal=self, sender=sender, **named)
               ^^^^^^^^^^^^^^^^^^^^^^^^^^^^^^^^^^^^^^^^^^^^^
  File "/usr/local/lib/python3.11/dist-packages/celery/fixups/django.py", line 97, in on_import_modules
    self.worker_fixup.validate_models()
  File "/usr/local/lib/python3.11/dist-packages/celery/fixups/django.py", line 137, in validate_models
    run_checks()
  File "/usr/local/lib/python3.11/dist-packages/django/core/checks/registry.py", line 88, in run_checks
    new_errors = check(app_configs=app_configs, databases=databases)
                 ^^^^^^^^^^^^^^^^^^^^^^^^^^^^^^^^^^^^^^^^^^^^^^^^^^^
  File "/usr/local/lib/python3.11/dist-packages/django/core/checks/urls.py", line 42, in check_url_namespaces_unique
    all_namespaces = _load_all_namespaces(resolver)
                     ^^^^^^^^^^^^^^^^^^^^^^^^^^^^^^
  File "/usr/local/lib/python3.11/dist-packages/django/core/checks/urls.py", line 61, in _load_all_namespaces
    url_patterns = getattr(resolver, "url_patterns", [])
                   ^^^^^^^^^^^^^^^^^^^^^^^^^^^^^^^^^^^^^
  File "/usr/local/lib/python3.11/dist-packages/django/utils/functional.py", line 57, in __get__
    res = instance.__dict__[self.name] = self.func(instance)
                                         ^^^^^^^^^^^^^^^^^^^
  File "/usr/local/lib/python3.11/dist-packages/django/urls/resolvers.py", line 715, in url_patterns
    patterns = getattr(self.urlconf_module, "urlpatterns", self.urlconf_module)
                       ^^^^^^^^^^^^^^^^^^^
  File "/usr/local/lib/python3.11/dist-packages/django/utils/functional.py", line 57, in __get__
    res = instance.__dict__[self.name] = self.func(instance)
                                         ^^^^^^^^^^^^^^^^^^^
  File "/usr/local/lib/python3.11/dist-packages/django/urls/resolvers.py", line 708, in urlconf_module
    return import_module(self.urlconf_name)
           ^^^^^^^^^^^^^^^^^^^^^^^^^^^^^^^^
  File "/usr/lib/python3.11/importlib/__init__.py", line 126, in import_module
    return _bootstrap._gcd_import(name[level:], package, level)
           ^^^^^^^^^^^^^^^^^^^^^^^^^^^^^^^^^^^^^^^^^^^^^^^^^^^^
  File "<frozen importlib._bootstrap>", line 1206, in _gcd_import
  File "<frozen importlib._bootstrap>", line 1178, in _find_and_load
  File "<frozen importlib._bootstrap>", line 1149, in _find_and_load_unlocked
  File "<frozen importlib._bootstrap>", line 690, in _load_unlocked
  File "<frozen importlib._bootstrap_external>", line 940, in exec_module
  File "<frozen importlib._bootstrap>", line 241, in _call_with_frames_removed
  File "/app/django_celery_example/urls.py", line 23, in <module>
    from polls.views import JournalJsonArrayOfDOUViewSet, DetailSingleJournalOfDOUViewSet
  File "/app/polls/views.py", line 16, in <module>
    from .services import JournalJsonArrayOfDOUService, DetailSingleJournalOfDOUService
  File "/app/polls/services.py", line 2, in <module>
    from trigger_web_scraping_dou_api.models import JournalJsonArrayOfDOU, DetailSingleJournalOfDOU
ModuleNotFoundError: No module named 'trigger_web_scraping_dou_api'
2024-01-26 20:55:31,315 - celery.utils.dispatch.signal - ERROR - Signal handler <bound method DjangoFixup.on_import_modules of <celery.fixups.django.DjangoFixup object at 0x7f8b350c0150>> raised: ModuleNotFoundError("No module named 'trigger_web_scraping_dou_api'")
Traceback (most recent call last):
  File "/usr/local/lib/python3.11/dist-packages/celery/utils/dispatch/signal.py", line 276, in send
    response = receiver(signal=self, sender=sender, **named)
               ^^^^^^^^^^^^^^^^^^^^^^^^^^^^^^^^^^^^^^^^^^^^^
  File "/usr/local/lib/python3.11/dist-packages/celery/fixups/django.py", line 97, in on_import_modules
    self.worker_fixup.validate_models()
  File "/usr/local/lib/python3.11/dist-packages/celery/fixups/django.py", line 137, in validate_models
    run_checks()
  File "/usr/local/lib/python3.11/dist-packages/django/core/checks/registry.py", line 88, in run_checks
    new_errors = check(app_configs=app_configs, databases=databases)
                 ^^^^^^^^^^^^^^^^^^^^^^^^^^^^^^^^^^^^^^^^^^^^^^^^^^^
  File "/usr/local/lib/python3.11/dist-packages/django/core/checks/urls.py", line 42, in check_url_namespaces_unique
    all_namespaces = _load_all_namespaces(resolver)
                     ^^^^^^^^^^^^^^^^^^^^^^^^^^^^^^
  File "/usr/local/lib/python3.11/dist-packages/django/core/checks/urls.py", line 61, in _load_all_namespaces
    url_patterns = getattr(resolver, "url_patterns", [])
                   ^^^^^^^^^^^^^^^^^^^^^^^^^^^^^^^^^^^^^
  File "/usr/local/lib/python3.11/dist-packages/django/utils/functional.py", line 57, in __get__
    res = instance.__dict__[self.name] = self.func(instance)
                                         ^^^^^^^^^^^^^^^^^^^
  File "/usr/local/lib/python3.11/dist-packages/django/urls/resolvers.py", line 715, in url_patterns
    patterns = getattr(self.urlconf_module, "urlpatterns", self.urlconf_module)
                       ^^^^^^^^^^^^^^^^^^^
  File "/usr/local/lib/python3.11/dist-packages/django/utils/functional.py", line 57, in __get__
    res = instance.__dict__[self.name] = self.func(instance)
                                         ^^^^^^^^^^^^^^^^^^^
  File "/usr/local/lib/python3.11/dist-packages/django/urls/resolvers.py", line 708, in urlconf_module
    return import_module(self.urlconf_name)
           ^^^^^^^^^^^^^^^^^^^^^^^^^^^^^^^^
  File "/usr/lib/python3.11/importlib/__init__.py", line 126, in import_module
    return _bootstrap._gcd_import(name[level:], package, level)
           ^^^^^^^^^^^^^^^^^^^^^^^^^^^^^^^^^^^^^^^^^^^^^^^^^^^^
  File "<frozen importlib._bootstrap>", line 1206, in _gcd_import
  File "<frozen importlib._bootstrap>", line 1178, in _find_and_load
  File "<frozen importlib._bootstrap>", line 1149, in _find_and_load_unlocked
  File "<frozen importlib._bootstrap>", line 690, in _load_unlocked
  File "<frozen importlib._bootstrap_external>", line 940, in exec_module
  File "<frozen importlib._bootstrap>", line 241, in _call_with_frames_removed
  File "/app/django_celery_example/urls.py", line 23, in <module>
    from polls.views import JournalJsonArrayOfDOUViewSet, DetailSingleJournalOfDOUViewSet
  File "/app/polls/views.py", line 18, in <module>
    from polls.serializers import JournalJsonArrayOfDOUSerializer, DetailSingleJournalOfDOUSerializer
  File "/app/polls/serializers.py", line 1, in <module>
    from trigger_web_scraping_dou_api.models import JournalJsonArrayOfDOU
ModuleNotFoundError: No module named 'trigger_web_scraping_dou_api'
2024-01-26 20:55:31,348 - celery.utils.dispatch.signal - ERROR - Signal handler <bound method DjangoFixup.on_import_modules of <celery.fixups.django.DjangoFixup object at 0x7fae610b42d0>> raised: ModuleNotFoundError("No module named 'trigger_web_scraping_dou_api'")
Traceback (most recent call last):
  File "/usr/local/lib/python3.11/dist-packages/celery/utils/dispatch/signal.py", line 276, in send
    response = receiver(signal=self, sender=sender, **named)
               ^^^^^^^^^^^^^^^^^^^^^^^^^^^^^^^^^^^^^^^^^^^^^
  File "/usr/local/lib/python3.11/dist-packages/celery/fixups/django.py", line 97, in on_import_modules
    self.worker_fixup.validate_models()
  File "/usr/local/lib/python3.11/dist-packages/celery/fixups/django.py", line 137, in validate_models
    run_checks()
  File "/usr/local/lib/python3.11/dist-packages/django/core/checks/registry.py", line 88, in run_checks
    new_errors = check(app_configs=app_configs, databases=databases)
                 ^^^^^^^^^^^^^^^^^^^^^^^^^^^^^^^^^^^^^^^^^^^^^^^^^^^
  File "/usr/local/lib/python3.11/dist-packages/django/core/checks/urls.py", line 42, in check_url_namespaces_unique
    all_namespaces = _load_all_namespaces(resolver)
                     ^^^^^^^^^^^^^^^^^^^^^^^^^^^^^^
  File "/usr/local/lib/python3.11/dist-packages/django/core/checks/urls.py", line 61, in _load_all_namespaces
    url_patterns = getattr(resolver, "url_patterns", [])
                   ^^^^^^^^^^^^^^^^^^^^^^^^^^^^^^^^^^^^^
  File "/usr/local/lib/python3.11/dist-packages/django/utils/functional.py", line 57, in __get__
    res = instance.__dict__[self.name] = self.func(instance)
                                         ^^^^^^^^^^^^^^^^^^^
  File "/usr/local/lib/python3.11/dist-packages/django/urls/resolvers.py", line 715, in url_patterns
    patterns = getattr(self.urlconf_module, "urlpatterns", self.urlconf_module)
                       ^^^^^^^^^^^^^^^^^^^
  File "/usr/local/lib/python3.11/dist-packages/django/utils/functional.py", line 57, in __get__
    res = instance.__dict__[self.name] = self.func(instance)
                                         ^^^^^^^^^^^^^^^^^^^
  File "/usr/local/lib/python3.11/dist-packages/django/urls/resolvers.py", line 708, in urlconf_module
    return import_module(self.urlconf_name)
           ^^^^^^^^^^^^^^^^^^^^^^^^^^^^^^^^
  File "/usr/lib/python3.11/importlib/__init__.py", line 126, in import_module
    return _bootstrap._gcd_import(name[level:], package, level)
           ^^^^^^^^^^^^^^^^^^^^^^^^^^^^^^^^^^^^^^^^^^^^^^^^^^^^
  File "<frozen importlib._bootstrap>", line 1206, in _gcd_import
  File "<frozen importlib._bootstrap>", line 1178, in _find_and_load
  File "<frozen importlib._bootstrap>", line 1149, in _find_and_load_unlocked
  File "<frozen importlib._bootstrap>", line 690, in _load_unlocked
  File "<frozen importlib._bootstrap_external>", line 940, in exec_module
  File "<frozen importlib._bootstrap>", line 241, in _call_with_frames_removed
  File "/app/django_celery_example/urls.py", line 23, in <module>
    from polls.views import JournalJsonArrayOfDOUViewSet, DetailSingleJournalOfDOUViewSet
  File "/app/polls/views.py", line 18, in <module>
    from polls.serializers import JournalJsonArrayOfDOUSerializer, DetailSingleJournalOfDOUSerializer
  File "/app/polls/serializers.py", line 1, in <module>
    from trigger_web_scraping_dou_api.models import JournalJsonArrayOfDOU
ModuleNotFoundError: No module named 'trigger_web_scraping_dou_api'
2024-01-26 20:56:30,115 - django.utils.autoreload - INFO - Watching for file changes with StatReloader
2024-01-26 20:56:32,954 - flower.command - INFO - Visit me at http://0.0.0.0:5555
2024-01-26 20:56:32,965 - flower.command - INFO - Broker: redis://redis:6379/0
2024-01-26 20:56:32,970 - flower.command - INFO - Registered tasks: 
['celery.accumulate',
 'celery.backend_cleanup',
 'celery.chain',
 'celery.chord',
 'celery.chord_unlock',
 'celery.chunks',
 'celery.group',
 'celery.map',
 'celery.starmap',
 'django_celery_example.celery.divide',
 'django_celery_example.celery.run_scraper_with_all_params_task']
2024-01-26 20:56:32,977 - kombu.mixins - INFO - Connected to redis://redis:6379/0
2024-01-26 20:57:27,286 - django.request - ERROR - Internal Server Error: /db_dou_api/detailsinglejournalofdouviewset/
Traceback (most recent call last):
  File "/usr/local/lib/python3.11/dist-packages/django/db/backends/utils.py", line 89, in _execute
    return self.cursor.execute(sql, params)
           ^^^^^^^^^^^^^^^^^^^^^^^^^^^^^^^^
psycopg2.errors.UndefinedTable: relation "polls_detailsinglejournalofdou" does not exist
LINE 1: SELECT COUNT(*) AS "__count" FROM "polls_detailsinglejournal...
                                          ^


The above exception was the direct cause of the following exception:

Traceback (most recent call last):
  File "/usr/local/lib/python3.11/dist-packages/django/core/handlers/exception.py", line 55, in inner
    response = get_response(request)
               ^^^^^^^^^^^^^^^^^^^^^
  File "/usr/local/lib/python3.11/dist-packages/django/core/handlers/base.py", line 197, in _get_response
    response = wrapped_callback(request, *callback_args, **callback_kwargs)
               ^^^^^^^^^^^^^^^^^^^^^^^^^^^^^^^^^^^^^^^^^^^^^^^^^^^^^^^^^^^^
  File "/usr/local/lib/python3.11/dist-packages/django/views/decorators/csrf.py", line 56, in wrapper_view
    return view_func(*args, **kwargs)
           ^^^^^^^^^^^^^^^^^^^^^^^^^^
  File "/usr/local/lib/python3.11/dist-packages/rest_framework/viewsets.py", line 125, in view
    return self.dispatch(request, *args, **kwargs)
           ^^^^^^^^^^^^^^^^^^^^^^^^^^^^^^^^^^^^^^^
  File "/usr/local/lib/python3.11/dist-packages/rest_framework/views.py", line 509, in dispatch
    response = self.handle_exception(exc)
               ^^^^^^^^^^^^^^^^^^^^^^^^^^
  File "/usr/local/lib/python3.11/dist-packages/rest_framework/views.py", line 469, in handle_exception
    self.raise_uncaught_exception(exc)
  File "/usr/local/lib/python3.11/dist-packages/rest_framework/views.py", line 480, in raise_uncaught_exception
    raise exc
  File "/usr/local/lib/python3.11/dist-packages/rest_framework/views.py", line 506, in dispatch
    response = handler(request, *args, **kwargs)
               ^^^^^^^^^^^^^^^^^^^^^^^^^^^^^^^^^
  File "/usr/local/lib/python3.11/dist-packages/rest_framework/mixins.py", line 40, in list
    page = self.paginate_queryset(queryset)
           ^^^^^^^^^^^^^^^^^^^^^^^^^^^^^^^^
  File "/usr/local/lib/python3.11/dist-packages/rest_framework/generics.py", line 171, in paginate_queryset
    return self.paginator.paginate_queryset(queryset, self.request, view=self)
           ^^^^^^^^^^^^^^^^^^^^^^^^^^^^^^^^^^^^^^^^^^^^^^^^^^^^^^^^^^^^^^^^^^^
  File "/usr/local/lib/python3.11/dist-packages/rest_framework/pagination.py", line 204, in paginate_queryset
    self.page = paginator.page(page_number)
                ^^^^^^^^^^^^^^^^^^^^^^^^^^^
  File "/usr/local/lib/python3.11/dist-packages/django/core/paginator.py", line 72, in page
    number = self.validate_number(number)
             ^^^^^^^^^^^^^^^^^^^^^^^^^^^^
  File "/usr/local/lib/python3.11/dist-packages/django/core/paginator.py", line 53, in validate_number
    if number > self.num_pages:
                ^^^^^^^^^^^^^^
  File "/usr/local/lib/python3.11/dist-packages/django/utils/functional.py", line 57, in __get__
    res = instance.__dict__[self.name] = self.func(instance)
                                         ^^^^^^^^^^^^^^^^^^^
  File "/usr/local/lib/python3.11/dist-packages/django/core/paginator.py", line 99, in num_pages
    if self.count == 0 and not self.allow_empty_first_page:
       ^^^^^^^^^^
  File "/usr/local/lib/python3.11/dist-packages/django/utils/functional.py", line 57, in __get__
    res = instance.__dict__[self.name] = self.func(instance)
                                         ^^^^^^^^^^^^^^^^^^^
  File "/usr/local/lib/python3.11/dist-packages/django/core/paginator.py", line 93, in count
    return c()
           ^^^
  File "/usr/local/lib/python3.11/dist-packages/django/db/models/query.py", line 608, in count
    return self.query.get_count(using=self.db)
           ^^^^^^^^^^^^^^^^^^^^^^^^^^^^^^^^^^^
  File "/usr/local/lib/python3.11/dist-packages/django/db/models/sql/query.py", line 568, in get_count
    return obj.get_aggregation(using, {"__count": Count("*")})["__count"]
           ^^^^^^^^^^^^^^^^^^^^^^^^^^^^^^^^^^^^^^^^^^^^^^^^^^^
  File "/usr/local/lib/python3.11/dist-packages/django/db/models/sql/query.py", line 554, in get_aggregation
    result = compiler.execute_sql(SINGLE)
             ^^^^^^^^^^^^^^^^^^^^^^^^^^^^
  File "/usr/local/lib/python3.11/dist-packages/django/db/models/sql/compiler.py", line 1562, in execute_sql
    cursor.execute(sql, params)
  File "/usr/local/lib/python3.11/dist-packages/debug_toolbar/panels/sql/tracking.py", line 252, in execute
    return self._record(super().execute, sql, params)
           ^^^^^^^^^^^^^^^^^^^^^^^^^^^^^^^^^^^^^^^^^^
  File "/usr/local/lib/python3.11/dist-packages/debug_toolbar/panels/sql/tracking.py", line 177, in _record
    return method(sql, params)
           ^^^^^^^^^^^^^^^^^^^
  File "/usr/local/lib/python3.11/dist-packages/django/db/backends/utils.py", line 102, in execute
    return super().execute(sql, params)
           ^^^^^^^^^^^^^^^^^^^^^^^^^^^^
  File "/usr/local/lib/python3.11/dist-packages/django/db/backends/utils.py", line 67, in execute
    return self._execute_with_wrappers(
           ^^^^^^^^^^^^^^^^^^^^^^^^^^^^
  File "/usr/local/lib/python3.11/dist-packages/django/db/backends/utils.py", line 80, in _execute_with_wrappers
    return executor(sql, params, many, context)
           ^^^^^^^^^^^^^^^^^^^^^^^^^^^^^^^^^^^^
  File "/usr/local/lib/python3.11/dist-packages/django/db/backends/utils.py", line 84, in _execute
    with self.db.wrap_database_errors:
  File "/usr/local/lib/python3.11/dist-packages/django/db/utils.py", line 91, in __exit__
    raise dj_exc_value.with_traceback(traceback) from exc_value
  File "/usr/local/lib/python3.11/dist-packages/django/db/backends/utils.py", line 89, in _execute
    return self.cursor.execute(sql, params)
           ^^^^^^^^^^^^^^^^^^^^^^^^^^^^^^^^
django.db.utils.ProgrammingError: relation "polls_detailsinglejournalofdou" does not exist
LINE 1: SELECT COUNT(*) AS "__count" FROM "polls_detailsinglejournal...
                                          ^

2024-01-26 21:02:28,090 - django.utils.autoreload - INFO - Watching for file changes with StatReloader
2024-01-26 21:02:30,803 - flower.command - INFO - Visit me at http://0.0.0.0:5555
2024-01-26 21:02:30,811 - flower.command - INFO - Broker: redis://redis:6379/0
2024-01-26 21:02:30,817 - flower.command - INFO - Registered tasks: 
['celery.accumulate',
 'celery.backend_cleanup',
 'celery.chain',
 'celery.chord',
 'celery.chord_unlock',
 'celery.chunks',
 'celery.group',
 'celery.map',
 'celery.starmap',
 'django_celery_example.celery.divide',
 'django_celery_example.celery.run_scraper_with_all_params_task']
2024-01-26 21:02:30,823 - kombu.mixins - INFO - Connected to redis://redis:6379/0
2024-01-26 21:03:08,224 - django.request - ERROR - Internal Server Error: /db_dou_api/detailsinglejournalofdouviewset/
Traceback (most recent call last):
  File "/usr/local/lib/python3.11/dist-packages/django/db/backends/utils.py", line 89, in _execute
    return self.cursor.execute(sql, params)
           ^^^^^^^^^^^^^^^^^^^^^^^^^^^^^^^^
psycopg2.errors.UndefinedTable: relation "polls_detailsinglejournalofdou" does not exist
LINE 1: SELECT COUNT(*) AS "__count" FROM "polls_detailsinglejournal...
                                          ^


The above exception was the direct cause of the following exception:

Traceback (most recent call last):
  File "/usr/local/lib/python3.11/dist-packages/django/core/handlers/exception.py", line 55, in inner
    response = get_response(request)
               ^^^^^^^^^^^^^^^^^^^^^
  File "/usr/local/lib/python3.11/dist-packages/django/core/handlers/base.py", line 197, in _get_response
    response = wrapped_callback(request, *callback_args, **callback_kwargs)
               ^^^^^^^^^^^^^^^^^^^^^^^^^^^^^^^^^^^^^^^^^^^^^^^^^^^^^^^^^^^^
  File "/usr/local/lib/python3.11/dist-packages/django/views/decorators/csrf.py", line 56, in wrapper_view
    return view_func(*args, **kwargs)
           ^^^^^^^^^^^^^^^^^^^^^^^^^^
  File "/usr/local/lib/python3.11/dist-packages/rest_framework/viewsets.py", line 125, in view
    return self.dispatch(request, *args, **kwargs)
           ^^^^^^^^^^^^^^^^^^^^^^^^^^^^^^^^^^^^^^^
  File "/usr/local/lib/python3.11/dist-packages/rest_framework/views.py", line 509, in dispatch
    response = self.handle_exception(exc)
               ^^^^^^^^^^^^^^^^^^^^^^^^^^
  File "/usr/local/lib/python3.11/dist-packages/rest_framework/views.py", line 469, in handle_exception
    self.raise_uncaught_exception(exc)
  File "/usr/local/lib/python3.11/dist-packages/rest_framework/views.py", line 480, in raise_uncaught_exception
    raise exc
  File "/usr/local/lib/python3.11/dist-packages/rest_framework/views.py", line 506, in dispatch
    response = handler(request, *args, **kwargs)
               ^^^^^^^^^^^^^^^^^^^^^^^^^^^^^^^^^
  File "/usr/local/lib/python3.11/dist-packages/rest_framework/mixins.py", line 40, in list
    page = self.paginate_queryset(queryset)
           ^^^^^^^^^^^^^^^^^^^^^^^^^^^^^^^^
  File "/usr/local/lib/python3.11/dist-packages/rest_framework/generics.py", line 171, in paginate_queryset
    return self.paginator.paginate_queryset(queryset, self.request, view=self)
           ^^^^^^^^^^^^^^^^^^^^^^^^^^^^^^^^^^^^^^^^^^^^^^^^^^^^^^^^^^^^^^^^^^^
  File "/usr/local/lib/python3.11/dist-packages/rest_framework/pagination.py", line 204, in paginate_queryset
    self.page = paginator.page(page_number)
                ^^^^^^^^^^^^^^^^^^^^^^^^^^^
  File "/usr/local/lib/python3.11/dist-packages/django/core/paginator.py", line 72, in page
    number = self.validate_number(number)
             ^^^^^^^^^^^^^^^^^^^^^^^^^^^^
  File "/usr/local/lib/python3.11/dist-packages/django/core/paginator.py", line 53, in validate_number
    if number > self.num_pages:
                ^^^^^^^^^^^^^^
  File "/usr/local/lib/python3.11/dist-packages/django/utils/functional.py", line 57, in __get__
    res = instance.__dict__[self.name] = self.func(instance)
                                         ^^^^^^^^^^^^^^^^^^^
  File "/usr/local/lib/python3.11/dist-packages/django/core/paginator.py", line 99, in num_pages
    if self.count == 0 and not self.allow_empty_first_page:
       ^^^^^^^^^^
  File "/usr/local/lib/python3.11/dist-packages/django/utils/functional.py", line 57, in __get__
    res = instance.__dict__[self.name] = self.func(instance)
                                         ^^^^^^^^^^^^^^^^^^^
  File "/usr/local/lib/python3.11/dist-packages/django/core/paginator.py", line 93, in count
    return c()
           ^^^
  File "/usr/local/lib/python3.11/dist-packages/django/db/models/query.py", line 608, in count
    return self.query.get_count(using=self.db)
           ^^^^^^^^^^^^^^^^^^^^^^^^^^^^^^^^^^^
  File "/usr/local/lib/python3.11/dist-packages/django/db/models/sql/query.py", line 568, in get_count
    return obj.get_aggregation(using, {"__count": Count("*")})["__count"]
           ^^^^^^^^^^^^^^^^^^^^^^^^^^^^^^^^^^^^^^^^^^^^^^^^^^^
  File "/usr/local/lib/python3.11/dist-packages/django/db/models/sql/query.py", line 554, in get_aggregation
    result = compiler.execute_sql(SINGLE)
             ^^^^^^^^^^^^^^^^^^^^^^^^^^^^
  File "/usr/local/lib/python3.11/dist-packages/django/db/models/sql/compiler.py", line 1562, in execute_sql
    cursor.execute(sql, params)
  File "/usr/local/lib/python3.11/dist-packages/debug_toolbar/panels/sql/tracking.py", line 252, in execute
    return self._record(super().execute, sql, params)
           ^^^^^^^^^^^^^^^^^^^^^^^^^^^^^^^^^^^^^^^^^^
  File "/usr/local/lib/python3.11/dist-packages/debug_toolbar/panels/sql/tracking.py", line 177, in _record
    return method(sql, params)
           ^^^^^^^^^^^^^^^^^^^
  File "/usr/local/lib/python3.11/dist-packages/django/db/backends/utils.py", line 102, in execute
    return super().execute(sql, params)
           ^^^^^^^^^^^^^^^^^^^^^^^^^^^^
  File "/usr/local/lib/python3.11/dist-packages/django/db/backends/utils.py", line 67, in execute
    return self._execute_with_wrappers(
           ^^^^^^^^^^^^^^^^^^^^^^^^^^^^
  File "/usr/local/lib/python3.11/dist-packages/django/db/backends/utils.py", line 80, in _execute_with_wrappers
    return executor(sql, params, many, context)
           ^^^^^^^^^^^^^^^^^^^^^^^^^^^^^^^^^^^^
  File "/usr/local/lib/python3.11/dist-packages/django/db/backends/utils.py", line 84, in _execute
    with self.db.wrap_database_errors:
  File "/usr/local/lib/python3.11/dist-packages/django/db/utils.py", line 91, in __exit__
    raise dj_exc_value.with_traceback(traceback) from exc_value
  File "/usr/local/lib/python3.11/dist-packages/django/db/backends/utils.py", line 89, in _execute
    return self.cursor.execute(sql, params)
           ^^^^^^^^^^^^^^^^^^^^^^^^^^^^^^^^
django.db.utils.ProgrammingError: relation "polls_detailsinglejournalofdou" does not exist
LINE 1: SELECT COUNT(*) AS "__count" FROM "polls_detailsinglejournal...
                                          ^

2024-01-26 21:04:23,284 - django.utils.autoreload - INFO - Watching for file changes with StatReloader
2024-01-26 21:04:24,242 - flower.command - INFO - Visit me at http://0.0.0.0:5555
2024-01-26 21:04:24,254 - flower.command - INFO - Broker: redis://redis:6379/0
2024-01-26 21:04:24,275 - flower.command - INFO - Registered tasks: 
['celery.accumulate',
 'celery.backend_cleanup',
 'celery.chain',
 'celery.chord',
 'celery.chord_unlock',
 'celery.chunks',
 'celery.group',
 'celery.map',
 'celery.starmap',
 'django_celery_example.celery.divide',
 'django_celery_example.celery.run_scraper_with_all_params_task']
2024-01-26 21:04:24,294 - kombu.mixins - INFO - Connected to redis://redis:6379/0
2024-01-26 21:12:51,778 - django.utils.autoreload - INFO - /app/polls/views.py changed, reloading.
2024-01-26 21:12:53,303 - django.utils.autoreload - INFO - Watching for file changes with StatReloader
2024-01-26 21:13:16,512 - django.request - ERROR - Internal Server Error: /trigger_web_scraping_dou_api/
Traceback (most recent call last):
  File "/usr/local/lib/python3.11/dist-packages/django/core/handlers/exception.py", line 55, in inner
    response = get_response(request)
               ^^^^^^^^^^^^^^^^^^^^^
  File "/usr/local/lib/python3.11/dist-packages/django/core/handlers/base.py", line 197, in _get_response
    response = wrapped_callback(request, *callback_args, **callback_kwargs)
               ^^^^^^^^^^^^^^^^^^^^^^^^^^^^^^^^^^^^^^^^^^^^^^^^^^^^^^^^^^^^
  File "/usr/local/lib/python3.11/dist-packages/django/views/decorators/csrf.py", line 56, in wrapper_view
    return view_func(*args, **kwargs)
           ^^^^^^^^^^^^^^^^^^^^^^^^^^
  File "/usr/local/lib/python3.11/dist-packages/django/views/generic/base.py", line 104, in view
    return self.dispatch(request, *args, **kwargs)
           ^^^^^^^^^^^^^^^^^^^^^^^^^^^^^^^^^^^^^^^
  File "/usr/local/lib/python3.11/dist-packages/rest_framework/views.py", line 509, in dispatch
    response = self.handle_exception(exc)
               ^^^^^^^^^^^^^^^^^^^^^^^^^^
  File "/usr/local/lib/python3.11/dist-packages/rest_framework/views.py", line 469, in handle_exception
    self.raise_uncaught_exception(exc)
  File "/usr/local/lib/python3.11/dist-packages/rest_framework/views.py", line 480, in raise_uncaught_exception
    raise exc
  File "/usr/local/lib/python3.11/dist-packages/rest_framework/views.py", line 506, in dispatch
    response = handler(request, *args, **kwargs)
               ^^^^^^^^^^^^^^^^^^^^^^^^^^^^^^^^^
  File "/app/polls/views.py", line 59, in get
    return self.handle_URL_empty_params(saveInDBFlag, detailDOUJournalFlag, balancerFlag)
           ^^^^^^^^^^^^^^^^^^^^^^^^^^^^^^^^^^^^^^^^^^^^^^^^^^^^^^^^^^^^^^^^^^^^^^^^^^^^^^
  File "/app/polls/views.py", line 263, in handle_URL_empty_params
    result = list(executor.map(call_my_task, args_tasks))
             ^^^^^^^^^^^^^^^^^^^^^^^^^^^^^^^^^^^^^^^^^^^^
  File "/usr/lib/python3.11/concurrent/futures/_base.py", line 619, in result_iterator
    yield _result_or_cancel(fs.pop())
          ^^^^^^^^^^^^^^^^^^^^^^^^^^^
  File "/usr/lib/python3.11/concurrent/futures/_base.py", line 317, in _result_or_cancel
    return fut.result(timeout)
           ^^^^^^^^^^^^^^^^^^^
  File "/usr/lib/python3.11/concurrent/futures/_base.py", line 456, in result
    return self.__get_result()
           ^^^^^^^^^^^^^^^^^^^
  File "/usr/lib/python3.11/concurrent/futures/_base.py", line 401, in __get_result
    raise self._exception
  File "/usr/lib/python3.11/concurrent/futures/thread.py", line 58, in run
    result = self.fn(*self.args, **self.kwargs)
             ^^^^^^^^^^^^^^^^^^^^^^^^^^^^^^^^^^
  File "/app/polls/views.py", line 250, in call_my_task
    result_future_with_celery = run_scraper_with_all_params_task.delay(args)
                                ^^^^^^^^^^^^^^^^^^^^^^^^^^^^^^^^^^^^^^^^^^^^
  File "/usr/local/lib/python3.11/dist-packages/celery/app/task.py", line 444, in delay
    return self.apply_async(args, kwargs)
           ^^^^^^^^^^^^^^^^^^^^^^^^^^^^^^
  File "/usr/local/lib/python3.11/dist-packages/celery/app/task.py", line 559, in apply_async
    check_arguments(*(args or ()), **(kwargs or {}))
TypeError: run_scraper_with_all_params_task() missing 3 required positional arguments: 'data', 'detailDOUJournalFlag', and 'balancerFlag'
2024-01-26 21:13:16,812 - django.request - WARNING - Not Found: /favicon.ico
2024-01-26 21:14:58,569 - django.utils.autoreload - INFO - /app/polls/views.py changed, reloading.
2024-01-26 21:15:00,040 - django.utils.autoreload - INFO - Watching for file changes with StatReloader
2024-01-26 21:15:03,095 - django.request - ERROR - Internal Server Error: /trigger_web_scraping_dou_api/
Traceback (most recent call last):
  File "/usr/local/lib/python3.11/dist-packages/django/core/handlers/exception.py", line 55, in inner
    response = get_response(request)
               ^^^^^^^^^^^^^^^^^^^^^
  File "/usr/local/lib/python3.11/dist-packages/django/core/handlers/base.py", line 197, in _get_response
    response = wrapped_callback(request, *callback_args, **callback_kwargs)
               ^^^^^^^^^^^^^^^^^^^^^^^^^^^^^^^^^^^^^^^^^^^^^^^^^^^^^^^^^^^^
  File "/usr/local/lib/python3.11/dist-packages/django/views/decorators/csrf.py", line 56, in wrapper_view
    return view_func(*args, **kwargs)
           ^^^^^^^^^^^^^^^^^^^^^^^^^^
  File "/usr/local/lib/python3.11/dist-packages/django/views/generic/base.py", line 104, in view
    return self.dispatch(request, *args, **kwargs)
           ^^^^^^^^^^^^^^^^^^^^^^^^^^^^^^^^^^^^^^^
  File "/usr/local/lib/python3.11/dist-packages/rest_framework/views.py", line 509, in dispatch
    response = self.handle_exception(exc)
               ^^^^^^^^^^^^^^^^^^^^^^^^^^
  File "/usr/local/lib/python3.11/dist-packages/rest_framework/views.py", line 469, in handle_exception
    self.raise_uncaught_exception(exc)
  File "/usr/local/lib/python3.11/dist-packages/rest_framework/views.py", line 480, in raise_uncaught_exception
    raise exc
  File "/usr/local/lib/python3.11/dist-packages/rest_framework/views.py", line 506, in dispatch
    response = handler(request, *args, **kwargs)
               ^^^^^^^^^^^^^^^^^^^^^^^^^^^^^^^^^
  File "/app/polls/views.py", line 59, in get
    return self.handle_URL_empty_params(saveInDBFlag, detailDOUJournalFlag, balancerFlag)
           ^^^^^^^^^^^^^^^^^^^^^^^^^^^^^^^^^^^^^^^^^^^^^^^^^^^^^^^^^^^^^^^^^^^^^^^^^^^^^^
  File "/app/polls/views.py", line 263, in handle_URL_empty_params
    result = list(executor.map(call_my_task, [args_tasks]))
             ^^^^^^^^^^^^^^^^^^^^^^^^^^^^^^^^^^^^^^^^^^^^^^
  File "/usr/lib/python3.11/concurrent/futures/_base.py", line 619, in result_iterator
    yield _result_or_cancel(fs.pop())
          ^^^^^^^^^^^^^^^^^^^^^^^^^^^
  File "/usr/lib/python3.11/concurrent/futures/_base.py", line 317, in _result_or_cancel
    return fut.result(timeout)
           ^^^^^^^^^^^^^^^^^^^
  File "/usr/lib/python3.11/concurrent/futures/_base.py", line 456, in result
    return self.__get_result()
           ^^^^^^^^^^^^^^^^^^^
  File "/usr/lib/python3.11/concurrent/futures/_base.py", line 401, in __get_result
    raise self._exception
  File "/usr/lib/python3.11/concurrent/futures/thread.py", line 58, in run
    result = self.fn(*self.args, **self.kwargs)
             ^^^^^^^^^^^^^^^^^^^^^^^^^^^^^^^^^^
  File "/app/polls/views.py", line 250, in call_my_task
    result_future_with_celery = run_scraper_with_all_params_task.delay(args)
                                ^^^^^^^^^^^^^^^^^^^^^^^^^^^^^^^^^^^^^^^^^^^^
  File "/usr/local/lib/python3.11/dist-packages/celery/app/task.py", line 444, in delay
    return self.apply_async(args, kwargs)
           ^^^^^^^^^^^^^^^^^^^^^^^^^^^^^^
  File "/usr/local/lib/python3.11/dist-packages/celery/app/task.py", line 559, in apply_async
    check_arguments(*(args or ()), **(kwargs or {}))
TypeError: run_scraper_with_all_params_task() missing 3 required positional arguments: 'data', 'detailDOUJournalFlag', and 'balancerFlag'
2024-01-26 21:17:24,453 - django.utils.autoreload - INFO - /app/polls/views.py changed, reloading.
2024-01-26 21:17:25,523 - django.utils.autoreload - INFO - Watching for file changes with StatReloader
2024-01-26 21:17:29,709 - django.request - ERROR - Internal Server Error: /trigger_web_scraping_dou_api/
Traceback (most recent call last):
  File "/usr/local/lib/python3.11/dist-packages/django/core/handlers/exception.py", line 55, in inner
    response = get_response(request)
               ^^^^^^^^^^^^^^^^^^^^^
  File "/usr/local/lib/python3.11/dist-packages/django/core/handlers/base.py", line 197, in _get_response
    response = wrapped_callback(request, *callback_args, **callback_kwargs)
               ^^^^^^^^^^^^^^^^^^^^^^^^^^^^^^^^^^^^^^^^^^^^^^^^^^^^^^^^^^^^
  File "/usr/local/lib/python3.11/dist-packages/django/views/decorators/csrf.py", line 56, in wrapper_view
    return view_func(*args, **kwargs)
           ^^^^^^^^^^^^^^^^^^^^^^^^^^
  File "/usr/local/lib/python3.11/dist-packages/django/views/generic/base.py", line 104, in view
    return self.dispatch(request, *args, **kwargs)
           ^^^^^^^^^^^^^^^^^^^^^^^^^^^^^^^^^^^^^^^
  File "/usr/local/lib/python3.11/dist-packages/rest_framework/views.py", line 509, in dispatch
    response = self.handle_exception(exc)
               ^^^^^^^^^^^^^^^^^^^^^^^^^^
  File "/usr/local/lib/python3.11/dist-packages/rest_framework/views.py", line 469, in handle_exception
    self.raise_uncaught_exception(exc)
  File "/usr/local/lib/python3.11/dist-packages/rest_framework/views.py", line 480, in raise_uncaught_exception
    raise exc
  File "/usr/local/lib/python3.11/dist-packages/rest_framework/views.py", line 506, in dispatch
    response = handler(request, *args, **kwargs)
               ^^^^^^^^^^^^^^^^^^^^^^^^^^^^^^^^^
  File "/app/polls/views.py", line 59, in get
    return self.handle_URL_empty_params(saveInDBFlag, detailDOUJournalFlag, balancerFlag)
           ^^^^^^^^^^^^^^^^^^^^^^^^^^^^^^^^^^^^^^^^^^^^^^^^^^^^^^^^^^^^^^^^^^^^^^^^^^^^^^
  File "/app/polls/views.py", line 263, in handle_URL_empty_params
    result = list(executor.map(call_my_task, [args_tasks]))
             ^^^^^^^^^^^^^^^^^^^^^^^^^^^^^^^^^^^^^^^^^^^^^^
  File "/usr/lib/python3.11/concurrent/futures/_base.py", line 619, in result_iterator
    yield _result_or_cancel(fs.pop())
          ^^^^^^^^^^^^^^^^^^^^^^^^^^^
  File "/usr/lib/python3.11/concurrent/futures/_base.py", line 317, in _result_or_cancel
    return fut.result(timeout)
           ^^^^^^^^^^^^^^^^^^^
  File "/usr/lib/python3.11/concurrent/futures/_base.py", line 456, in result
    return self.__get_result()
           ^^^^^^^^^^^^^^^^^^^
  File "/usr/lib/python3.11/concurrent/futures/_base.py", line 401, in __get_result
    raise self._exception
  File "/usr/lib/python3.11/concurrent/futures/thread.py", line 58, in run
    result = self.fn(*self.args, **self.kwargs)
             ^^^^^^^^^^^^^^^^^^^^^^^^^^^^^^^^^^
  File "/app/polls/views.py", line 250, in call_my_task
    result_future_with_celery = run_scraper_with_all_params_task.delay(args)
                                ^^^^^^^^^^^^^^^^^^^^^^^^^^^^^^^^^^^^^^^^^^^^
  File "/usr/local/lib/python3.11/dist-packages/celery/app/task.py", line 444, in delay
    return self.apply_async(args, kwargs)
           ^^^^^^^^^^^^^^^^^^^^^^^^^^^^^^
  File "/usr/local/lib/python3.11/dist-packages/celery/app/task.py", line 559, in apply_async
    check_arguments(*(args or ()), **(kwargs or {}))
TypeError: run_scraper_with_all_params_task() missing 3 required positional arguments: 'data', 'detailDOUJournalFlag', and 'balancerFlag'
2024-01-26 21:17:29,862 - django.request - WARNING - Not Found: /favicon.ico
2024-01-26 21:24:40,939 - django.utils.autoreload - INFO - /app/polls/views.py changed, reloading.
2024-01-26 21:24:41,915 - django.utils.autoreload - INFO - Watching for file changes with StatReloader
2024-01-26 21:40:55,330 - django.utils.autoreload - INFO - /app/django_celery_example/celery.py changed, reloading.
2024-01-26 21:53:47,856 - django.utils.autoreload - INFO - Watching for file changes with StatReloader
2024-01-26 21:53:50,656 - flower.command - INFO - Visit me at http://0.0.0.0:5555
2024-01-26 21:53:50,673 - flower.command - INFO - Broker: redis://redis:6379/0
2024-01-26 21:53:50,686 - flower.command - INFO - Registered tasks: 
['celery.accumulate',
 'celery.backend_cleanup',
 'celery.chain',
 'celery.chord',
 'celery.chord_unlock',
 'celery.chunks',
 'celery.group',
 'celery.map',
 'celery.starmap',
 'django_celery_example.celery.divide',
 'django_celery_example.celery.insert_into_distinct_details_journals_and_date_normalize',
 'django_celery_example.celery.insert_into_distinct_dontDetails_journals_and_date_normalize',
 'django_celery_example.celery.run_scraper_with_all_params_task']
2024-01-26 21:53:50,708 - kombu.mixins - INFO - Connected to redis://redis:6379/0
2024-01-26 21:54:31,925 - django.request - ERROR - Internal Server Error: /trigger_web_scraping_dou_api/
Traceback (most recent call last):
  File "/usr/local/lib/python3.11/dist-packages/django/core/handlers/exception.py", line 55, in inner
    response = get_response(request)
               ^^^^^^^^^^^^^^^^^^^^^
  File "/usr/local/lib/python3.11/dist-packages/django/core/handlers/base.py", line 197, in _get_response
    response = wrapped_callback(request, *callback_args, **callback_kwargs)
               ^^^^^^^^^^^^^^^^^^^^^^^^^^^^^^^^^^^^^^^^^^^^^^^^^^^^^^^^^^^^
  File "/usr/local/lib/python3.11/dist-packages/django/views/decorators/csrf.py", line 56, in wrapper_view
    return view_func(*args, **kwargs)
           ^^^^^^^^^^^^^^^^^^^^^^^^^^
  File "/usr/local/lib/python3.11/dist-packages/django/views/generic/base.py", line 104, in view
    return self.dispatch(request, *args, **kwargs)
           ^^^^^^^^^^^^^^^^^^^^^^^^^^^^^^^^^^^^^^^
  File "/usr/local/lib/python3.11/dist-packages/rest_framework/views.py", line 509, in dispatch
    response = self.handle_exception(exc)
               ^^^^^^^^^^^^^^^^^^^^^^^^^^
  File "/usr/local/lib/python3.11/dist-packages/rest_framework/views.py", line 469, in handle_exception
    self.raise_uncaught_exception(exc)
  File "/usr/local/lib/python3.11/dist-packages/rest_framework/views.py", line 480, in raise_uncaught_exception
    raise exc
  File "/usr/local/lib/python3.11/dist-packages/rest_framework/views.py", line 506, in dispatch
    response = handler(request, *args, **kwargs)
               ^^^^^^^^^^^^^^^^^^^^^^^^^^^^^^^^^
  File "/app/polls/views.py", line 59, in get
    return self.handle_URL_empty_params(saveInDBFlag, detailDOUJournalFlag, balancerFlag)
           ^^^^^^^^^^^^^^^^^^^^^^^^^^^^^^^^^^^^^^^^^^^^^^^^^^^^^^^^^^^^^^^^^^^^^^^^^^^^^^
  File "/app/polls/views.py", line 266, in handle_URL_empty_params
    result = list(executor.map(call_my_task, dous_list,
            ^^^^^^^^^^^^^^^^^^^^^^^^^^^^^^^^^^^^^^^^^^^
  File "/usr/lib/python3.11/concurrent/futures/_base.py", line 619, in result_iterator
    yield _result_or_cancel(fs.pop())
          ^^^^^^^^^^^^^^^^^^^^^^^^^^^
  File "/usr/lib/python3.11/concurrent/futures/_base.py", line 317, in _result_or_cancel
    return fut.result(timeout)
           ^^^^^^^^^^^^^^^^^^^
  File "/usr/lib/python3.11/concurrent/futures/_base.py", line 456, in result
    return self.__get_result()
           ^^^^^^^^^^^^^^^^^^^
  File "/usr/lib/python3.11/concurrent/futures/_base.py", line 401, in __get_result
    raise self._exception
  File "/usr/lib/python3.11/concurrent/futures/thread.py", line 58, in run
    result = self.fn(*self.args, **self.kwargs)
             ^^^^^^^^^^^^^^^^^^^^^^^^^^^^^^^^^^
  File "/app/polls/views.py", line 249, in call_my_task
    result_future_with_celery = run_scraper_with_all_params_task.delay(secao,
                               ^^^^^^^^^^^^^^^^^^^^^^^^^^^^^^^^^^^^^^^^^^^^^^
  File "/usr/local/lib/python3.11/dist-packages/celery/app/task.py", line 444, in delay
    return self.apply_async(args, kwargs)
           ^^^^^^^^^^^^^^^^^^^^^^^^^^^^^^
  File "/usr/local/lib/python3.11/dist-packages/celery/app/task.py", line 559, in apply_async
    check_arguments(*(args or ()), **(kwargs or {}))
TypeError: run_scraper_with_all_params_task() missing 1 required positional argument: 'saveInDBFlag'
2024-01-26 21:56:46,232 - django.utils.autoreload - INFO - /app/django_celery_example/celery.py changed, reloading.
2024-01-26 21:56:48,183 - django.utils.autoreload - INFO - Watching for file changes with StatReloader
2024-01-26 21:56:51,704 - django.utils.autoreload - INFO - /app/polls/views.py changed, reloading.
2024-01-26 21:56:53,238 - django.utils.autoreload - INFO - Watching for file changes with StatReloader
2024-01-26 22:00:37,015 - django.utils.autoreload - INFO - Watching for file changes with StatReloader
2024-01-26 22:00:38,819 - flower.command - INFO - Visit me at http://0.0.0.0:5555
2024-01-26 22:00:38,828 - flower.command - INFO - Broker: redis://redis:6379/0
2024-01-26 22:00:38,837 - flower.command - INFO - Registered tasks: 
['celery.accumulate',
 'celery.backend_cleanup',
 'celery.chain',
 'celery.chord',
 'celery.chord_unlock',
 'celery.chunks',
 'celery.group',
 'celery.map',
 'celery.starmap',
 'django_celery_example.celery.divide',
 'django_celery_example.celery.insert_into_distinct_details_journals_and_date_normalize',
 'django_celery_example.celery.insert_into_distinct_dontDetails_journals_and_date_normalize',
 'django_celery_example.celery.run_scraper_with_all_params_task']
2024-01-26 22:00:38,846 - kombu.mixins - INFO - Connected to redis://redis:6379/0
2024-01-26 22:05:28,431 - django.utils.autoreload - INFO - Watching for file changes with StatReloader
2024-01-26 22:05:30,083 - flower.command - INFO - Visit me at http://0.0.0.0:5555
2024-01-26 22:05:30,089 - flower.command - INFO - Broker: redis://redis:6379/0
2024-01-26 22:05:30,095 - flower.command - INFO - Registered tasks: 
['celery.accumulate',
 'celery.backend_cleanup',
 'celery.chain',
 'celery.chord',
 'celery.chord_unlock',
 'celery.chunks',
 'celery.group',
 'celery.map',
 'celery.starmap',
 'django_celery_example.celery.divide',
 'django_celery_example.celery.insert_into_distinct_details_journals_and_date_normalize',
 'django_celery_example.celery.insert_into_distinct_dontDetails_journals_and_date_normalize',
 'django_celery_example.celery.run_scraper_with_all_params_task']
2024-01-26 22:05:30,104 - kombu.mixins - INFO - Connected to redis://redis:6379/0
2024-01-26 22:11:19,691 - django.request - ERROR - Internal Server Error: /trigger_web_scraping_dou_api/
Traceback (most recent call last):
  File "/usr/local/lib/python3.11/dist-packages/django/core/handlers/exception.py", line 55, in inner
    response = get_response(request)
               ^^^^^^^^^^^^^^^^^^^^^
  File "/usr/local/lib/python3.11/dist-packages/django/core/handlers/base.py", line 197, in _get_response
    response = wrapped_callback(request, *callback_args, **callback_kwargs)
               ^^^^^^^^^^^^^^^^^^^^^^^^^^^^^^^^^^^^^^^^^^^^^^^^^^^^^^^^^^^^
  File "/usr/local/lib/python3.11/dist-packages/django/views/decorators/csrf.py", line 56, in wrapper_view
    return view_func(*args, **kwargs)
           ^^^^^^^^^^^^^^^^^^^^^^^^^^
  File "/usr/local/lib/python3.11/dist-packages/django/views/generic/base.py", line 104, in view
    return self.dispatch(request, *args, **kwargs)
           ^^^^^^^^^^^^^^^^^^^^^^^^^^^^^^^^^^^^^^^
  File "/usr/local/lib/python3.11/dist-packages/rest_framework/views.py", line 509, in dispatch
    response = self.handle_exception(exc)
               ^^^^^^^^^^^^^^^^^^^^^^^^^^
  File "/usr/local/lib/python3.11/dist-packages/rest_framework/views.py", line 469, in handle_exception
    self.raise_uncaught_exception(exc)
  File "/usr/local/lib/python3.11/dist-packages/rest_framework/views.py", line 480, in raise_uncaught_exception
    raise exc
  File "/usr/local/lib/python3.11/dist-packages/rest_framework/views.py", line 506, in dispatch
    response = handler(request, *args, **kwargs)
               ^^^^^^^^^^^^^^^^^^^^^^^^^^^^^^^^^
  File "/app/polls/views.py", line 61, in get
    return self.handle_URL_empty_params(saveInDBFlag, detailDOUJournalFlag, balancerFlag)
           ^^^^^^^^^^^^^^^^^^^^^^^^^^^^^^^^^^^^^^^^^^^^^^^^^^^^^^^^^^^^^^^^^^^^^^^^^^^^^^
  File "/app/polls/views.py", line 277, in handle_URL_empty_params
    result = list(executor.map(call_my_task, dous_list,
            ^^^^^^^^^^^^^^^^^^^^^^^^^^^^^^^^^^^^^^^^^^^
  File "/usr/lib/python3.11/concurrent/futures/_base.py", line 619, in result_iterator
    yield _result_or_cancel(fs.pop())
          ^^^^^^^^^^^^^^^^^^^^^^^^^^^
  File "/usr/lib/python3.11/concurrent/futures/_base.py", line 317, in _result_or_cancel
    return fut.result(timeout)
           ^^^^^^^^^^^^^^^^^^^
  File "/usr/lib/python3.11/concurrent/futures/_base.py", line 456, in result
    return self.__get_result()
           ^^^^^^^^^^^^^^^^^^^
  File "/usr/lib/python3.11/concurrent/futures/_base.py", line 401, in __get_result
    raise self._exception
  File "/usr/lib/python3.11/concurrent/futures/thread.py", line 58, in run
    result = self.fn(*self.args, **self.kwargs)
             ^^^^^^^^^^^^^^^^^^^^^^^^^^^^^^^^^^
  File "/app/polls/views.py", line 270, in call_my_task
    result = result_future_with_celery.get()
             ^^^^^^^^^^^^^^^^^^^^^^^^^^^^^^^
  File "/usr/local/lib/python3.11/dist-packages/celery/result.py", line 251, in get
    return self.backend.wait_for_pending(
           ^^^^^^^^^^^^^^^^^^^^^^^^^^^^^^
  File "/usr/local/lib/python3.11/dist-packages/celery/backends/asynchronous.py", line 223, in wait_for_pending
    return result.maybe_throw(callback=callback, propagate=propagate)
           ^^^^^^^^^^^^^^^^^^^^^^^^^^^^^^^^^^^^^^^^^^^^^^^^^^^^^^^^^^
  File "/usr/local/lib/python3.11/dist-packages/celery/result.py", line 365, in maybe_throw
    self.throw(value, self._to_remote_traceback(tb))
  File "/usr/local/lib/python3.11/dist-packages/celery/result.py", line 358, in throw
    self.on_ready.throw(*args, **kwargs)
  File "/usr/local/lib/python3.11/dist-packages/vine/promises.py", line 235, in throw
    reraise(type(exc), exc, tb)
  File "/usr/local/lib/python3.11/dist-packages/vine/utils.py", line 27, in reraise
    raise value
TypeError: insert_into_distinct_details_journals_and_date_normalize() takes 1 positional argument but 2 were given
2024-01-27 03:40:13,956 - flower.events - ERROR - Failed to capture events: 'Connection closed by server.', trying again in 1 seconds.
